# Практика #1
**Приведите пример кода с генерацией двух исключений, одно из которых будет "перхвачено", а другое приведет к аварийной остановке.**

```java
public class Main {
    public static void main(String[] args) {
        try {
            // Генерация первого исключения, которое будет "перехвачено"
            int result = 10 / 0; // Деление на ноль
        } catch (ArithmeticException e) {
            System.out.println("Caught ArithmeticException: " + e.getMessage());
        }

        // Генерация второго исключения, которое приведет к остановке
        String str = null;
        System.out.println(str.length()); // Попытка вызвать метод через null
    }
}
```